```
try…except..finally
处理流程：
try:  #认为可能出错的代码段，放在try中执行
	print('try....')
	r=10/0  # 出错，抛出ZeroDivisionError错误，下条语句不会被执行
	print('result:',r)
except ZeroDivisionError as e: # 捕获错误，没有错误则不会执行下条语句
	print('except:',e)
else:           # 当没有错误的时候，会执行else语句
print('Success')
finally:  # 无论如何都会执行
	print('finally')
print('END')

python所有的错误都是从BaseException类派生的，常见的错误类型如下：
BaseException
 +-- SystemExit
 +-- KeyboardInterrupt
 +-- GeneratorExit
 +-- Exception
      +-- StopIteration
      +-- StopAsyncIteration
      +-- ArithmeticError
      |    +-- FloatingPointError
      |    +-- OverflowError
      |    +-- ZeroDivisionError
      +-- AssertionError
      +-- AttributeError
      +-- BufferError
      +-- EOFError
      +-- ImportError
           +-- ModuleNotFoundError
      +-- LookupError
      |    +-- IndexError
      |    +-- KeyError
      +-- MemoryError
      +-- NameError
      |    +-- UnboundLocalError
      +-- OSError
      |    +-- BlockingIOError
      |    +-- ChildProcessError
      |    +-- ConnectionError
      |    |    +-- BrokenPipeError
      |    |    +-- ConnectionAbortedError
      |    |    +-- ConnectionRefusedError
      |    |    +-- ConnectionResetError
      |    +-- FileExistsError
      |    +-- FileNotFoundError
      |    +-- InterruptedError
      |    +-- IsADirectoryError
      |    +-- NotADirectoryError
      |    +-- PermissionError
      |    +-- ProcessLookupError
      |    +-- TimeoutError
      +-- ReferenceError
      +-- RuntimeError
      |    +-- NotImplementedError
      |    +-- RecursionError
      +-- SyntaxError
      |    +-- IndentationError
      |         +-- TabError
      +-- SystemError
      +-- TypeError
      +-- ValueError
      |    +-- UnicodeError
      |         +-- UnicodeDecodeError
      |         +-- UnicodeEncodeError
      |         +-- UnicodeTranslateError
      +-- Warning
           +-- DeprecationWarning
           +-- PendingDeprecationWarning
           +-- RuntimeWarning
           +-- SyntaxWarning
           +-- UserWarning
           +-- FutureWarning
           +-- ImportWarning
           +-- UnicodeWarning
           +-- BytesWarning
           +-- ResourceWarning

捕获错误的调用堆栈
如果错误没有被捕获，则会一直往上抛，最后被python解释器捕获，打印一个错误信息，然后退出
def  foo(s):
	return  10/int(s)

def  bar(s):
	return  foo(s)*2

def  main():
	bar('0')

main()

Traceback (most recent call last):   # 错误跟踪信息
  File "C:/Users/xingyanl/PycharmProjects/first_python/helloworld.py", line 121, in <module>
    main()    #main函数的121行出错了
  File "C:/Users/xingyanl/PycharmProjects/first_python/helloworld.py", line 119, in main
    bar('0')  # 原因是第119行，调用bar('0')出错了
  File "C:/Users/xingyanl/PycharmProjects/first_python/helloworld.py", line 116, in bar
    return foo(s) * 2  # 继续浏览
  File "C:/Users/xingyanl/PycharmProjects/first_python/helloworld.py", line 113, in foo
    return 10 / int(s)  # 最终原因
ZeroDivisionError: division by zero  # int(s)没出错，错误的是除以0了
# 异常退出
Process finished with exit code 1


记录错误
python使用logging模块记录错误的信息：
def  main():
	try:
		bar('0')
	except  Exception  as e:
		logging.exception(e)
		
ERROR:root:division by zero
Traceback (most recent call last):
  File "C:/Users/xingyanl/PycharmProjects/first_python/helloworld.py", line 121, in main
    bar('0')
  File "C:/Users/xingyanl/PycharmProjects/first_python/helloworld.py", line 117, in bar
    return foo(s) * 2
  File "C:/Users/xingyanl/PycharmProjects/first_python/helloworld.py", line 114, in foo
    return 10 / int(s)
ZeroDivisionError: division by zero
#正常退出
Process finished with exit code 0

抛出错误
错误就是class，捕获错误就是捕获该类的一个实例，错误并不是凭空产生的，而是有意创建并抛出的
如果要抛出错误，首先要定义一个错误的class，选择好继承关系，然后用raise抛出一个错误的实例
class  FooError(ValueError):  # 除非特别需要，否则不自定义错误
pass
def  foo(s):
	n=int(s)
if n==0:
	raise FooError('invalid  value:%s' %s)
return 10/n
foo('0')

Traceback (most recent call last):
  File "C:/Users/xingyanl/PycharmProjects/first_python/helloworld.py", line 135, in <module>
    foo('0')
  File "C:/Users/xingyanl/PycharmProjects/first_python/helloworld.py", line 132, in foo
    raise FooError('invalid value: %s' %s)
__main__.FooError: invalid value: 0     # 自定义的抛出的错误

错误处理方式

def  foo(s):
	n=int(s)
	if  n==0:
		raise  ValueError('invalidvalue:%s'%s)  # 第一次raise
	return  10/n

def bar():
	try:
		foo('0')
	except   ValueError  as  e:
		print('ValueErrorxxxxx')
		raise   #再一次raise抛出去，在不带参数的情况下，会抛到最上层处理
bar()
Value Errorxxxxx
Traceback (most recent call last):
  File "C:/Users/xingyanl/PycharmProjects/first_python/helloworld.py", line 149, in <module>
    bar()
  File "C:/Users/xingyanl/PycharmProjects/first_python/helloworld.py", line 145, in bar
    foo('0')
  File "C:/Users/xingyanl/PycharmProjects/first_python/helloworld.py", line 140, in foo
    raise ValueError('invalid value: %s' %s)
ValueError: invalid value: 0

Process finished with exit code 1

```